Traceback (most recent call last):
  File "/home/conda/global/9764ad0fe205ee3ccb00b4474c3e6708e73fb3a628843d562645d7d1e21ccb8d-20231221-205006-476455-52-pangeo/lib/python3.11/site-packages/nbclient/client.py", line 778, in _async_poll_for_reply
    msg = await ensure_async(self.kc.shell_channel.get_msg(timeout=new_timeout))
          ^^^^^^^^^^^^^^^^^^^^^^^^^^^^^^^^^^^^^^^^^^^^^^^^^^^^^^^^^^^^^^^^^^^^^^
  File "/home/conda/global/9764ad0fe205ee3ccb00b4474c3e6708e73fb3a628843d562645d7d1e21ccb8d-20231221-205006-476455-52-pangeo/lib/python3.11/site-packages/jupyter_core/utils/__init__.py", line 188, in ensure_async
    result = await obj
             ^^^^^^^^^
  File "/home/conda/global/9764ad0fe205ee3ccb00b4474c3e6708e73fb3a628843d562645d7d1e21ccb8d-20231221-205006-476455-52-pangeo/lib/python3.11/site-packages/jupyter_client/channels.py", line 230, in get_msg
    raise Empty
_queue.Empty

During handling of the above exception, another exception occurred:

Traceback (most recent call last):
  File "/home/conda/global/9764ad0fe205ee3ccb00b4474c3e6708e73fb3a628843d562645d7d1e21ccb8d-20231221-205006-476455-52-pangeo/lib/python3.11/site-packages/jupyter_cache/executors/utils.py", line 58, in single_nb_execution
    executenb(
  File "/home/conda/global/9764ad0fe205ee3ccb00b4474c3e6708e73fb3a628843d562645d7d1e21ccb8d-20231221-205006-476455-52-pangeo/lib/python3.11/site-packages/nbclient/client.py", line 1305, in execute
    return NotebookClient(nb=nb, resources=resources, km=km, **kwargs).execute()
           ^^^^^^^^^^^^^^^^^^^^^^^^^^^^^^^^^^^^^^^^^^^^^^^^^^^^^^^^^^^^^^^^^^^^^
  File "/home/conda/global/9764ad0fe205ee3ccb00b4474c3e6708e73fb3a628843d562645d7d1e21ccb8d-20231221-205006-476455-52-pangeo/lib/python3.11/site-packages/jupyter_core/utils/__init__.py", line 172, in wrapped
    return loop.run_until_complete(inner)
           ^^^^^^^^^^^^^^^^^^^^^^^^^^^^^^
  File "/home/conda/global/9764ad0fe205ee3ccb00b4474c3e6708e73fb3a628843d562645d7d1e21ccb8d-20231221-205006-476455-52-pangeo/lib/python3.11/asyncio/base_events.py", line 653, in run_until_complete
    return future.result()
           ^^^^^^^^^^^^^^^
  File "/home/conda/global/9764ad0fe205ee3ccb00b4474c3e6708e73fb3a628843d562645d7d1e21ccb8d-20231221-205006-476455-52-pangeo/lib/python3.11/site-packages/nbclient/client.py", line 705, in async_execute
    await self.async_execute_cell(
  File "/home/conda/global/9764ad0fe205ee3ccb00b4474c3e6708e73fb3a628843d562645d7d1e21ccb8d-20231221-205006-476455-52-pangeo/lib/python3.11/site-packages/nbclient/client.py", line 1001, in async_execute_cell
    exec_reply = await self.task_poll_for_reply
                 ^^^^^^^^^^^^^^^^^^^^^^^^^^^^^^
  File "/home/conda/global/9764ad0fe205ee3ccb00b4474c3e6708e73fb3a628843d562645d7d1e21ccb8d-20231221-205006-476455-52-pangeo/lib/python3.11/site-packages/nbclient/client.py", line 802, in _async_poll_for_reply
    error_on_timeout_execute_reply = await self._async_handle_timeout(timeout, cell)
                                     ^^^^^^^^^^^^^^^^^^^^^^^^^^^^^^^^^^^^^^^^^^^^^^^
  File "/home/conda/global/9764ad0fe205ee3ccb00b4474c3e6708e73fb3a628843d562645d7d1e21ccb8d-20231221-205006-476455-52-pangeo/lib/python3.11/site-packages/nbclient/client.py", line 852, in _async_handle_timeout
    raise CellTimeoutError.error_from_timeout_and_cell(
nbclient.exceptions.CellTimeoutError: A cell timed out while it was being executed, after 600 seconds.
The message was: Cell execution timed out.
Here is a preview of the cell contents:
-------------------
%run ../../../environment_set_up/Start_Dask_Cluster_Nebari.ipynb
### Executes external 'helper to spin up a cluster of workers. 
-------------------

