Traceback (most recent call last):
  File "/home/conda/global/62a33dd6392d99cdb8c777bdb35cc7d662d7d9aa44389978b669d2393745af98-20231212-224809-899591-42-pangeo/lib/python3.11/site-packages/nbclient/client.py", line 778, in _async_poll_for_reply
    msg = await ensure_async(self.kc.shell_channel.get_msg(timeout=new_timeout))
          ^^^^^^^^^^^^^^^^^^^^^^^^^^^^^^^^^^^^^^^^^^^^^^^^^^^^^^^^^^^^^^^^^^^^^^
  File "/home/conda/global/62a33dd6392d99cdb8c777bdb35cc7d662d7d9aa44389978b669d2393745af98-20231212-224809-899591-42-pangeo/lib/python3.11/site-packages/jupyter_core/utils/__init__.py", line 189, in ensure_async
    result = await obj
             ^^^^^^^^^
  File "/home/conda/global/62a33dd6392d99cdb8c777bdb35cc7d662d7d9aa44389978b669d2393745af98-20231212-224809-899591-42-pangeo/lib/python3.11/site-packages/jupyter_client/channels.py", line 230, in get_msg
    raise Empty
_queue.Empty

During handling of the above exception, another exception occurred:

Traceback (most recent call last):
  File "/home/conda/global/62a33dd6392d99cdb8c777bdb35cc7d662d7d9aa44389978b669d2393745af98-20231212-224809-899591-42-pangeo/lib/python3.11/site-packages/jupyter_cache/executors/utils.py", line 58, in single_nb_execution
    executenb(
  File "/home/conda/global/62a33dd6392d99cdb8c777bdb35cc7d662d7d9aa44389978b669d2393745af98-20231212-224809-899591-42-pangeo/lib/python3.11/site-packages/nbclient/client.py", line 1305, in execute
    return NotebookClient(nb=nb, resources=resources, km=km, **kwargs).execute()
           ^^^^^^^^^^^^^^^^^^^^^^^^^^^^^^^^^^^^^^^^^^^^^^^^^^^^^^^^^^^^^^^^^^^^^
  File "/home/conda/global/62a33dd6392d99cdb8c777bdb35cc7d662d7d9aa44389978b669d2393745af98-20231212-224809-899591-42-pangeo/lib/python3.11/site-packages/jupyter_core/utils/__init__.py", line 173, in wrapped
    return loop.run_until_complete(inner)
           ^^^^^^^^^^^^^^^^^^^^^^^^^^^^^^
  File "/home/conda/global/62a33dd6392d99cdb8c777bdb35cc7d662d7d9aa44389978b669d2393745af98-20231212-224809-899591-42-pangeo/lib/python3.11/asyncio/base_events.py", line 653, in run_until_complete
    return future.result()
           ^^^^^^^^^^^^^^^
  File "/home/conda/global/62a33dd6392d99cdb8c777bdb35cc7d662d7d9aa44389978b669d2393745af98-20231212-224809-899591-42-pangeo/lib/python3.11/site-packages/nbclient/client.py", line 705, in async_execute
    await self.async_execute_cell(
  File "/home/conda/global/62a33dd6392d99cdb8c777bdb35cc7d662d7d9aa44389978b669d2393745af98-20231212-224809-899591-42-pangeo/lib/python3.11/site-packages/nbclient/client.py", line 1001, in async_execute_cell
    exec_reply = await self.task_poll_for_reply
                 ^^^^^^^^^^^^^^^^^^^^^^^^^^^^^^
  File "/home/conda/global/62a33dd6392d99cdb8c777bdb35cc7d662d7d9aa44389978b669d2393745af98-20231212-224809-899591-42-pangeo/lib/python3.11/site-packages/nbclient/client.py", line 802, in _async_poll_for_reply
    error_on_timeout_execute_reply = await self._async_handle_timeout(timeout, cell)
                                     ^^^^^^^^^^^^^^^^^^^^^^^^^^^^^^^^^^^^^^^^^^^^^^^
  File "/home/conda/global/62a33dd6392d99cdb8c777bdb35cc7d662d7d9aa44389978b669d2393745af98-20231212-224809-899591-42-pangeo/lib/python3.11/site-packages/nbclient/client.py", line 852, in _async_handle_timeout
    raise CellTimeoutError.error_from_timeout_and_cell(
nbclient.exceptions.CellTimeoutError: A cell timed out while it was being executed, after 600 seconds.
The message was: Cell execution timed out.
Here is a preview of the cell contents:
-------------------
from dask.distributed import progress, performance_report

with performance_report(filename="dask-report.html"):
    r = result.execute(retries=10)  
-------------------

